<?xml version="1.0"?>
<robot name="robot">

  <!-- ==================== 材质定义 ==================== -->
  <material name="blue">
    <color rgba="0.0 0.0 0.8 1.0"/>
  </material>
  <material name="black">
    <color rgba="0.1 0.1 0.1 1.0"/>
  </material>
  <material name="white">
    <color rgba="1.0 1.0 1.0 1.0"/>
  </material>
  <material name="red">
    <color rgba="0.8 0.0 0.0 1.0"/>
  </material>
  <material name="green">
    <color rgba="0.0 0.8 0.0 1.0"/>
  </material>
  <material name="grey">
    <color rgba="0.5 0.5 0.5 1.0"/>
  </material>

  <!-- ==================== 底盘 (base_link) ==================== -->
  <!-- 圆柱体底盘: 半径 0.15m, 高度 0.08m -->
  <link name="base_link">
    <visual>
      <origin xyz="0 0 0" rpy="0 0 0"/>
      <geometry>
        <cylinder radius="0.15" length="0.08"/>
      </geometry>
      <material name="blue"/>
    </visual>
    <collision>
      <origin xyz="0 0 0" rpy="0 0 0"/>
      <geometry>
        <cylinder radius="0.15" length="0.08"/>
      </geometry>
    </collision>
    <inertial>
      <origin xyz="0 0 0" rpy="0 0 0"/>
      <mass value="10.0"/>
      <inertia
        ixx="0.0616" ixy="0.0"   ixz="0.0"
        iyy="0.0616" iyz="0.0"
        izz="0.1125"/>
    </inertial>
  </link>

  <!-- ==================== 左驱动轮 ==================== -->
  <!-- 圆柱体轮子: 半径 0.05m, 宽度 0.04m -->
  <joint name="left_wheel_joint" type="continuous">
    <parent link="base_link"/>
    <child link="left_wheel_link"/>
    <origin xyz="0 0.15 0" rpy="1.5708 0 0"/>
    <axis xyz="0 0 1"/>
  </joint>

  <link name="left_wheel_link">
    <visual>
      <origin xyz="0 0 0" rpy="0 0 0"/>
      <geometry>
        <cylinder radius="0.05" length="0.04"/>
      </geometry>
      <material name="black"/>
    </visual>
    <collision>
      <origin xyz="0 0 0" rpy="0 0 0"/>
      <geometry>
        <cylinder radius="0.05" length="0.04"/>
      </geometry>
    </collision>
    <inertial>
      <origin xyz="0 0 0" rpy="0 0 0"/>
      <mass value="0.5"/>
      <inertia
        ixx="0.000379" ixy="0.0"   ixz="0.0"
        iyy="0.000379" iyz="0.0"
        izz="0.000625"/>
    </inertial>
  </link>

  <!-- ==================== 右驱动轮 ==================== -->
  <joint name="right_wheel_joint" type="continuous">
    <parent link="base_link"/>
    <child link="right_wheel_link"/>
    <origin xyz="0 -0.15 0" rpy="1.5708 0 0"/>
    <axis xyz="0 0 1"/>
  </joint>

  <link name="right_wheel_link">
    <visual>
      <origin xyz="0 0 0" rpy="0 0 0"/>
      <geometry>
        <cylinder radius="0.05" length="0.04"/>
      </geometry>
      <material name="black"/>
    </visual>
    <collision>
      <origin xyz="0 0 0" rpy="0 0 0"/>
      <geometry>
        <cylinder radius="0.05" length="0.04"/>
      </geometry>
    </collision>
    <inertial>
      <origin xyz="0 0 0" rpy="0 0 0"/>
      <mass value="0.5"/>
      <inertia
        ixx="0.000379" ixy="0.0"   ixz="0.0"
        iyy="0.000379" iyz="0.0"
        izz="0.000625"/>
    </inertial>
  </link>

  <!-- ==================== 前万向轮 (支撑轮) ==================== -->
  <!-- 球体万向轮: 半径 0.02m -->
  <joint name="front_caster_joint" type="fixed">
    <parent link="base_link"/>
    <child link="front_caster_link"/>
    <origin xyz="0.12 0 -0.03" rpy="0 0 0"/>
  </joint>

  <link name="front_caster_link">
    <visual>
      <origin xyz="0 0 0" rpy="0 0 0"/>
      <geometry>
        <sphere radius="0.02"/>
      </geometry>
      <material name="white"/>
    </visual>
    <collision>
      <origin xyz="0 0 0" rpy="0 0 0"/>
      <geometry>
        <sphere radius="0.02"/>
      </geometry>
    </collision>
    <inertial>
      <origin xyz="0 0 0" rpy="0 0 0"/>
      <mass value="0.1"/>
      <inertia
        ixx="0.000016" ixy="0.0"   ixz="0.0"
        iyy="0.000016" iyz="0.0"
        izz="0.000016"/>
    </inertial>
  </link>

  <!-- ==================== 雷达 (Lidar) ==================== -->
  <!-- 安装在底盘顶部中心 -->
  <joint name="laser_joint" type="fixed">
    <parent link="base_link"/>
    <child link="laser_link"/>
    <origin xyz="0 0 0.09" rpy="0 0 0"/>
  </joint>

  <link name="laser_link">
    <visual>
      <origin xyz="0 0 0" rpy="0 0 0"/>
      <geometry>
        <cylinder radius="0.05" length="0.03"/>
      </geometry>
      <material name="grey"/>
    </visual>
    <collision>
      <origin xyz="0 0 0" rpy="0 0 0"/>
      <geometry>
        <cylinder radius="0.05" length="0.03"/>
      </geometry>
    </collision>
    <inertial>
      <origin xyz="0 0 0" rpy="0 0 0"/>
      <mass value="0.2"/>
      <inertia
        ixx="0.0001" ixy="0.0"   ixz="0.0"
        iyy="0.0001" iyz="0.0"
        izz="0.000025"/>
    </inertial>
  </link>

  <!-- ==================== 相机 (Camera) ==================== -->
  <!-- 安装在底盘前端偏上位置 -->
  <joint name="camera_joint" type="fixed">
    <parent link="base_link"/>
    <child link="camera_link"/>
    <origin xyz="0.15 0 0.02" rpy="0 0 0"/>
  </joint>

  <link name="camera_link">
    <visual>
      <origin xyz="0 0 0" rpy="0 0 0"/>
      <geometry>
        <box size="0.03 0.06 0.04"/>
      </geometry>
      <material name="red"/>
    </visual>
    <collision>
      <origin xyz="0 0 0" rpy="0 0 0"/>
      <geometry>
        <box size="0.03 0.06 0.04"/>
      </geometry>
    </collision>
    <inertial>
      <origin xyz="0 0 0" rpy="0 0 0"/>
      <mass value="0.1"/>
      <inertia
        ixx="0.0000417" ixy="0.0"   ixz="0.0"
        iyy="0.0000417" iyz="0.0"
        izz="0.0000417"/>
    </inertial>
  </link>

  <!-- 相机光学坐标系 (Z轴朝前, X轴朝右, Y轴朝下) -->
  <joint name="camera_optical_joint" type="fixed">
    <parent link="camera_link"/>
    <child link="camera_optical_frame"/>
    <origin xyz="0 0 0" rpy="-1.5708 0 -1.5708"/>
  </joint>

  <link name="camera_optical_frame"/>

  <!-- ==================== IMU ==================== -->
  <!-- 安装在底盘中心偏上位置 -->
  <joint name="imu_joint" type="fixed">
    <parent link="base_link"/>
    <child link="imu_link"/>
    <origin xyz="0 0 0.02" rpy="0 0 0"/>
  </joint>

  <link name="imu_link">
    <visual>
      <origin xyz="0 0 0" rpy="0 0 0"/>
      <geometry>
        <box size="0.04 0.04 0.02"/>
      </geometry>
      <material name="green"/>
    </visual>
    <collision>
      <origin xyz="0 0 0" rpy="0 0 0"/>
      <geometry>
        <box size="0.04 0.04 0.02"/>
      </geometry>
    </collision>
    <inertial>
      <origin xyz="0 0 0" rpy="0 0 0"/>
      <mass value="0.05"/>
      <inertia
        ixx="0.00001" ixy="0.0"   ixz="0.0"
        iyy="0.00001" iyz="0.0"
        izz="0.00001"/>
    </inertial>
  </link>

  <!-- ==================== Gz Sim 差速驱动插件 ==================== -->
  <!-- 轮式里程计: 发布 /odom 话题和 odom → base_link TF -->
  <gazebo>
    <plugin filename="gz-sim-diff-drive-system"
            name="gz::sim::systems::DiffDrive">
      <left_joint>left_wheel_joint</left_joint>
      <right_joint>right_wheel_joint</right_joint>
      <wheel_separation>0.3</wheel_separation>
      <wheel_radius>0.05</wheel_radius>
      <odom_publish_frequency>100</odom_publish_frequency>
      <topic>cmd_vel</topic>
    </plugin>
  </gazebo>

  <!-- ==================== Gz Sim 雷达插件 ==================== -->
  <gazebo reference="laser_link">
    <sensor type="gpu_lidar" name="laser">
      <always_on>true</always_on>
      <update_rate>10</update_rate>
      <visualize>true</visualize>
      <topic>/scan</topic>
      <gz_frame_id>laser_link</gz_frame_id>
      <lidar>
        <scan>
          <horizontal>
            <samples>360</samples>
            <resolution>1</resolution>
            <min_angle>-3.14159</min_angle>
            <max_angle>3.14159</max_angle>
          </horizontal>
        </scan>
        <range>
          <min>0.1</min>
          <max>10.0</max>
          <resolution>0.01</resolution>
        </range>
      </lidar>
    </sensor>
  </gazebo>

  <!-- ==================== Gz Sim 相机插件 ==================== -->
  <!-- ROS 话题桥接由 ros_gz_bridge 在 launch 中配置 -->
  <gazebo reference="camera_link">
    <sensor type="camera" name="camera">
      <always_on>true</always_on>
      <update_rate>30</update_rate>
      <visualize>true</visualize>
      <topic>/camera</topic>
      <gz_frame_id>camera_optical_frame</gz_frame_id>
      <camera>
        <horizontal_fov>1.047</horizontal_fov>
        <image>
          <width>640</width>
          <height>480</height>
          <format>R8G8B8</format>
        </image>
        <clip>
          <near>0.01</near>
          <far>100</far>
        </clip>
      </camera>
    </sensor>
  </gazebo>

  <!-- ==================== Gz Sim IMU 插件 ==================== -->
  <!-- ROS 话题桥接由 ros_gz_bridge 在 launch 中配置 -->
  <gazebo reference="imu_link">
    <sensor type="imu" name="imu">
      <always_on>true</always_on>
      <update_rate>100</update_rate>
      <visualize>true</visualize>
      <topic>/imu</topic>
      <gz_frame_id>imu_link</gz_frame_id>
    </sensor>
  </gazebo>

</robot>